Workbook

Sheet Zones
A1: # | B1: Name | C1: X | D1: Y | E1: Z | F1: Notes
A2: 1 | B2: StartingPoint | C2: 194.56 | D2: 837.7 | E2: 5.02
A3: 2 | B3: Xform | C3: 194.53 | D3: 844.47 | E3: 5
A4: 3 | B4: Xform_01 | C4: 194.27 | D4: 854.82 | E4: 4.91
A5: 4 | B5: Xform_02 | C5: 193.69 | D5: 866.91 | E5: 4.81
A6: 5 | B6: Xform_03 | C6: 197.58 | D6: 881.94 | E6: 4.58
A7: 6 | B7: Xform_04 | C7: 205.73 | D7: 892.9 | E7: 4.48
A8: 7 | B8: Xform_05 | C8: 194.56 | D8: 892.78 | E8: 4.52
A9: 8 | B9: Xform_06 | C9: 186.55 | D9: 892.65 | E9: 4.59
A10: 9 | B10: Xform_07 | C10: 177.32 | D10: 892.32 | E10: 4.72
A11: 10 | B11: Xform_08 | C11: 170.43 | D11: 891.91 | E11: 4.79
A12: 11 | B12: Xform_09 | C12: 168.39 | D12: 897.2 | E12: 4.72
A13: 12 | B13: Xform_10 | C13: 214.33 | D13: 893.07 | E13: 4.44
... A35: 34 | B35: Xform_32 | C35: 297.68 | D35: 910.02 | E35: 21.06

Sheet Links
A1: From | B1: To | C1: Bidirectional | D1: Enabled | E1: StraightDist_m (참고) | F1: From_Z | G1: To_Z | H1: ΔZ (auto) | I1: Notes
A2: Xform | B2: Xform_01 | C2: Y | D2: Y | E2: =IFERROR(ROUND(SQRT((VLOOKUP(A2,Zones!$B$2:$E$35,2,FALSE())-VLOOKUP(B2,Zones!$B$2:$E$35,2,FALSE()))^2+(VLOOKUP(A2,Zones!$B$2:$E$35,3,FALSE())-VLOOKUP(B2,Zones!$B$2:$E$35,3,FALSE()))^2+(VLOOKUP(A2,Zones!$B$2:$E$35,4,FALSE())-VLOOKUP(B2,Zones!$B$2:$E$35,4,FALSE()))^2),2),"") -> 10.35 | F2: =IFERROR(VLOOKUP(A2,Zones!$B$2:$E$35,4,FALSE()),"") -> 5 | G2: =IFERROR(VLOOKUP(B2,Zones!$B$2:$E$35,4,FALSE()),"") -> 4.91 | H2: =IFERROR(G2-F2,"") -> -0.09
A3: Xform_01 | B3: Xform_02 | C3: Y | D3: Y | E3: =IFERROR(ROUND(SQRT((VLOOKUP(A3,Zones!$B$2:$E$35,2,FALSE())-VLOOKUP(B3,Zones!$B$2:$E$35,2,FALSE()))^2+(VLOOKUP(A3,Zones!$B$2:$E$35,3,FALSE())-VLOOKUP(B3,Zones!$B$2:$E$35,3,FALSE()))^2+(VLOOKUP(A3,Zones!$B$2:$E$35,4,FALSE())-VLOOKUP(B3,Zones!$B$2:$E$35,4,FALSE()))^2),2),"") -> 12.1 | F3: =IFERROR(VLOOKUP(A3,Zones!$B$2:$E$35,4,FALSE()),"") -> 4.91 | G3: =IFERROR(VLOOKUP(B3,Zones!$B$2:$E$35,4,FALSE()),"") -> 4.81 | H3: =IFERROR(G3-F3,"") -> -0.1
A4: Xform_02 | B4: Xform_03 | C4: Y | D4: Y | E4: =IFERROR(ROUND(SQRT((VLOOKUP(A4,Zones!$B$2:$E$35,2,FALSE())-VLOOKUP(B4,Zones!$B$2:$E$35,2,FALSE()))^2+(VLOOKUP(A4,Zones!$B$2:$E$35,3,FALSE())-VLOOKUP(B4,Zones!$B$2:$E$35,3,FALSE()))^2+(VLOOKUP(A4,Zones!$B$2:$E$35,4,FALSE())-VLOOKUP(B4,Zones!$B$2:$E$35,4,FALSE()))^2),2),"") -> 15.53 | F4: =IFERROR(VLOOKUP(A4,Zones!$B$2:$E$35,4,FALSE()),"") -> 4.81 | G4: =IFERROR(VLOOKUP(B4,Zones!$B$2:$E$35,4,FALSE()),"") -> 4.58 | H4: =IFERROR(G4-F4,"") -> -0.23
A5: Xform_03 | B5: Xform_04 | C5: Y | D5: Y | E5: =IFERROR(ROUND(SQRT((VLOOKUP(A5,Zones!$B$2:$E$35,2,FALSE())-VLOOKUP(B5,Zones!$B$2:$E$35,2,FALSE()))^2+(VLOOKUP(A5,Zones!$B$2:$E$35,3,FALSE())-VLOOKUP(B5,Zones!$B$2:$E$35,3,FALSE()))^2+(VLOOKUP(A5,Zones!$B$2:$E$35,4,FALSE())-VLOOKUP(B5,Zones!$B$2:$E$35,4,FALSE()))^2),2),"") -> 13.66 | F5: =IFERROR(VLOOKUP(A5,Zones!$B$2:$E$35,4,FALSE()),"") -> 4.58 | G5: =IFERROR(VLOOKUP(B5,Zones!$B$2:$E$35,4,FALSE()),"") -> 4.48 | H5: =IFERROR(G5-F5,"") -> -0.1
A6: Xform_03 | B6: Xform_05 | C6: Y | D6: Y | E6: =IFERROR(ROUND(SQRT((VLOOKUP(A6,Zones!$B$2:$E$35,2,FALSE())-VLOOKUP(B6,Zones!$B$2:$E$35,2,FALSE()))^2+(VLOOKUP(A6,Zones!$B$2:$E$35,3,FALSE())-VLOOKUP(B6,Zones!$B$2:$E$35,3,FALSE()))^2+(VLOOKUP(A6,Zones!$B$2:$E$35,4,FALSE())-VLOOKUP(B6,Zones!$B$2:$E$35,4,FALSE()))^2),2),"") -> 11.25 | F6: =IFERROR(VLOOKUP(A6,Zones!$B$2:$E$35,4,FALSE()),"") -> 4.58 | G6: =IFERROR(VLOOKUP(B6,Zones!$B$2:$E$35,4,FALSE()),"") -> 4.52 | H6: =IFERROR(G6-F6,"") -> -0.06
A7: Xform_05 | B7: Xform_06 | C7: Y | D7: Y | E7: =IFERROR(ROUND(SQRT((VLOOKUP(A7,Zones!$B$2:$E$35,2,FALSE())-VLOOKUP(B7,Zones!$B$2:$E$35,2,FALSE()))^2+(VLOOKUP(A7,Zones!$B$2:$E$35,3,FALSE())-VLOOKUP(B7,Zones!$B$2:$E$35,3,FALSE()))^2+(VLOOKUP(A7,Zones!$B$2:$E$35,4,FALSE())-VLOOKUP(B7,Zones!$B$2:$E$35,4,FALSE()))^2),2),"") -> 8.01 | F7: =IFERROR(VLOOKUP(A7,Zones!$B$2:$E$35,4,FALSE()),"") -> 4.52 | G7: =IFERROR(VLOOKUP(B7,Zones!$B$2:$E$35,4,FALSE()),"") -> 4.59 | H7: =IFERROR(G7-F7,"") -> 0.07
A8: Xform_04 | B8: Xform_05 | C8: Y | D8: Y | E8: =IFERROR(ROUND(SQRT((VLOOKUP(A8,Zones!$B$2:$E$35,2,FALSE())-VLOOKUP(B8,Zones!$B$2:$E$35,2,FALSE()))^2+(VLOOKUP(A8,Zones!$B$2:$E$35,3,FALSE())-VLOOKUP(B8,Zones!$B$2:$E$35,3,FALSE()))^2+(VLOOKUP(A8,Zones!$B$2:$E$35,4,FALSE())-VLOOKUP(B8,Zones!$B$2:$E$35,4,FALSE()))^2),2),"") -> 11.17 | F8: =IFERROR(VLOOKUP(A8,Zones!$B$2:$E$35,4,FALSE()),"") -> 4.48 | G8: =IFERROR(VLOOKUP(B8,Zones!$B$2:$E$35,4,FALSE()),"") -> 4.52 | H8: =IFERROR(G8-F8,"") -> 0.04
A9: Xform_06 | B9: Xform_07 | C9: Y | D9: Y | E9: =IFERROR(ROUND(SQRT((VLOOKUP(A9,Zones!$B$2:$E$35,2,FALSE())-VLOOKUP(B9,Zones!$B$2:$E$35,2,FALSE()))^2+(VLOOKUP(A9,Zones!$B$2:$E$35,3,FALSE())-VLOOKUP(B9,Zones!$B$2:$E$35,3,FALSE()))^2+(VLOOKUP(A9,Zones!$B$2:$E$35,4,FALSE())-VLOOKUP(B9,Zones!$B$2:$E$35,4,FALSE()))^2),2),"") -> 9.24 | F9: =IFERROR(VLOOKUP(A9,Zones!$B$2:$E$35,4,FALSE()),"") -> 4.59 | G9: =IFERROR(VLOOKUP(B9,Zones!$B$2:$E$35,4,FALSE()),"") -> 4.72 | H9: =IFERROR(G9-F9,"") -> 0.13
A10: Xform_07 | B10: Xform_08 | C10: Y | D10: Y | E10: =IFERROR(ROUND(SQRT((VLOOKUP(A10,Zones!$B$2:$E$35,2,FALSE())-VLOOKUP(B10,Zones!$B$2:$E$35,2,FALSE()))^2+(VLOOKUP(A10,Zones!$B$2:$E$35,3,FALSE())-VLOOKUP(B10,Zones!$B$2:$E$35,3,FALSE()))^2+(VLOOKUP(A10,Zones!$B$2:$E$35,4,FALSE())-VLOOKUP(B10,Zones!$B$2:$E$35,4,FALSE()))^2),2),"") -> 6.9 | F10: =IFERROR(VLOOKUP(A10,Zones!$B$2:$E$35,4,FALSE()),"") -> 4.72 | G10: =IFERROR(VLOOKUP(B10,Zones!$B$2:$E$35,4,FALSE()),"") -> 4.79 | H10: =IFERROR(G10-F10,"") -> 0.07
A11: Xform_08 | B11: Xform_09 | C11: Y | D11: Y | E11: =IFERROR(ROUND(SQRT((VLOOKUP(A11,Zones!$B$2:$E$35,2,FALSE())-VLOOKUP(B11,Zones!$B$2:$E$35,2,FALSE()))^2+(VLOOKUP(A11,Zones!$B$2:$E$35,3,FALSE())-VLOOKUP(B11,Zones!$B$2:$E$35,3,FALSE()))^2+(VLOOKUP(A11,Zones!$B$2:$E$35,4,FALSE())-VLOOKUP(B11,Zones!$B$2:$E$35,4,FALSE()))^2),2),"") -> 5.67 | F11: =IFERROR(VLOOKUP(A11,Zones!$B$2:$E$35,4,FALSE()),"") -> 4.79 | G11: =IFERROR(VLOOKUP(B11,Zones!$B$2:$E$35,4,FALSE()),"") -> 4.72 | H11: =IFERROR(G11-F11,"") -> -0.07 | I11: Xform_09는 TP_A 의 최종 목적 좌표
A12: Xform_04 | B12: Xform_10 | C12: Y | D12: Y | E12: =IFERROR(ROUND(SQRT((VLOOKUP(A12,Zones!$B$2:$E$35,2,FALSE())-VLOOKUP(B12,Zones!$B$2:$E$35,2,FALSE()))^2+(VLOOKUP(A12,Zones!$B$2:$E$35,3,FALSE())-VLOOKUP(B12,Zones!$B$2:$E$35,3,FALSE()))^2+(VLOOKUP(A12,Zones!$B$2:$E$35,4,FALSE())-VLOOKUP(B12,Zones!$B$2:$E$35,4,FALSE()))^2),2),"") -> 8.6 | F12: =IFERROR(VLOOKUP(A12,Zones!$B$2:$E$35,4,FALSE()),"") -> 4.48 | G12: =IFERROR(VLOOKUP(B12,Zones!$B$2:$E$35,4,FALSE()),"") -> 4.44 | H12: =IFERROR(G12-F12,"") -> -0.04
A13: Xform_10 | B13: Xform_11 | C13: Y | D13: Y | E13: =IFERROR(ROUND(SQRT((VLOOKUP(A13,Zones!$B$2:$E$35,2,FALSE())-VLOOKUP(B13,Zones!$B$2:$E$35,2,FALSE()))^2+(VLOOKUP(A13,Zones!$B$2:$E$35,3,FALSE())-VLOOKUP(B13,Zones!$B$2:$E$35,3,FALSE()))^2+(VLOOKUP(A13,Zones!$B$2:$E$35,4,FALSE())-VLOOKUP(B13,Zones!$B$2:$E$35,4,FALSE()))^2),2),"") -> 8.49 | F13: =IFERROR(VLOOKUP(A13,Zones!$B$2:$E$35,4,FALSE()),"") -> 4.44 | G13: =IFERROR(VLOOKUP(B13,Zones!$B$2:$E$35,4,FALSE()),"") -> 4.42 | H13: =IFERROR(G13-F13,"") -> -0.02
A14: Xform_11 | B14: Xform_12 | C14: Y | D14: Y | E14: =IFERROR(ROUND(SQRT((VLOOKUP(A14,Zones!$B$2:$E$35,2,FALSE())-VLOOKUP(B14,Zones!$B$2:$E$35,2,FALSE()))^2+(VLOOKUP(A14,Zones!$B$2:$E$35,3,FALSE())-VLOOKUP(B14,Zones!$B$2:$E$35,3,FALSE()))^2+(VLOOKUP(A14,Zones!$B$2:$E$35,4,FALSE())-VLOOKUP(B14,Zones!$B$2:$E$35,4,FALSE()))^2),2),"") -> 12.05 | F14: =IFERROR(VLOOKUP(A14,Zones!$B$2:$E$35,4,FALSE()),"") -> 4.42 | G14: =IFERROR(VLOOKUP(B14,Zones!$B$2:$E$35,4,FALSE()),"") -> 5.02 | H14: =IFERROR(G14-F14,"") -> 0.6
A15: Xform_12 | B15: Xform_13 | C15: Y | D15: Y | E15: =IFERROR(ROUND(SQRT((VLOOKUP(A15,Zones!$B$2:$E$35,2,FALSE())-VLOOKUP(B15,Zones!$B$2:$E$35,2,FALSE()))^2+(VLOOKUP(A15,Zones!$B$2:$E$35,3,FALSE())-VLOOKUP(B15,Zones!$B$2:$E$35,3,FALSE()))^2+(VLOOKUP(A15,Zones!$B$2:$E$35,4,FALSE())-VLOOKUP(B15,Zones!$B$2:$E$35,4,FALSE()))^2),2),"") -> 9.84 | F15: =IFERROR(VLOOKUP(A15,Zones!$B$2:$E$35,4,FALSE()),"") -> 5.02 | G15: =IFERROR(VLOOKUP(B15,Zones!$B$2:$E$35,4,FALSE()),"") -> 7.21 | H15: =IFERROR(G15-F15,"") -> 2.19 | I15: Xform_13은 TP_B 의 최종 목적 좌표
A16: Xform_13 | B16: Xform_14 | C16: Y | D16: Y | E16: =IFERROR(ROUND(SQRT((VLOOKUP(A16,Zones!$B$2:$E$35,2,FALSE())-VLOOKUP(B16,Zones!$B$2:$E$35,2,FALSE()))^2+(VLOOKUP(A16,Zones!$B$2:$E$35,3,FALSE())-VLOOKUP(B16,Zones!$B$2:$E$35,3,FALSE()))^2+(VLOOKUP(A16,Zones!$B$2:$E$35,4,FALSE())-VLOOKUP(B16,Zones!$B$2:$E$35,4,FALSE()))^2),2),"") -> 7.82 | F16: =IFERROR(VLOOKUP(A16,Zones!$B$2:$E$35,4,FALSE()),"") -> 7.21 | G16: =IFERROR(VLOOKUP(B16,Zones!$B$2:$E$35,4,FALSE()),"") -> 10.1 | H16: =IFERROR(G16-F16,"") -> 2.89
A17: Xform_14 | B17: Xform_15 | C17: Y | D17: Y | E17: =IFERROR(ROUND(SQRT((VLOOKUP(A17,Zones!$B$2:$E$35,2,FALSE())-VLOOKUP(B17,Zones!$B$2:$E$35,2,FALSE()))^2+(VLOOKUP(A17,Zones!$B$2:$E$35,3,FALSE())-VLOOKUP(B17,Zones!$B$2:$E$35,3,FALSE()))^2+(VLOOKUP(A17,Zones!$B$2:$E$35,4,FALSE())-VLOOKUP(B17,Zones!$B$2:$E$35,4,FALSE()))^2),2),"") -> 9.07 | F17: =IFERROR(VLOOKUP(A17,Zones!$B$2:$E$35,4,FALSE()),"") -> 10.1 | G17: =IFERROR(VLOOKUP(B17,Zones!$B$2:$E$35,4,FALSE()),"") -> 12.13 | H17: =IFERROR(G17-F17,"") -> 2.03
A18: Xform_14 | B18: Xform_16 | C18: Y | D18: Y | E18: =IFERROR(ROUND(SQRT((VLOOKUP(A18,Zones!$B$2:$E$35,2,FALSE())-VLOOKUP(B18,Zones!$B$2:$E$35,2,FALSE()))^2+(VLOOKUP(A18,Zones!$B$2:$E$35,3,FALSE())-VLOOKUP(B18,Zones!$B$2:$E$35,3,FALSE()))^2+(VLOOKUP(A18,Zones!$B$2:$E$35,4,FALSE())-VLOOKUP(B18,Zones!$B$2:$E$35,4,FALSE()))^2),2),"") -> 7.22 | F18: =IFERROR(VLOOKUP(A18,Zones!$B$2:$E$35,4,FALSE()),"") -> 10.1 | G18: =IFERROR(VLOOKUP(B18,Zones!$B$2:$E$35,4,FALSE()),"") -> 12.5 | H18: =IFERROR(G18-F18,"") -> 2.4
A19: Xform_16 | B19: Xform_17 | C19: Y | D19: Y | E19: =IFERROR(ROUND(SQRT((VLOOKUP(A19,Zones!$B$2:$E$35,2,FALSE())-VLOOKUP(B19,Zones!$B$2:$E$35,2,FALSE()))^2+(VLOOKUP(A19,Zones!$B$2:$E$35,3,FALSE())-VLOOKUP(B19,Zones!$B$2:$E$35,3,FALSE()))^2+(VLOOKUP(A19,Zones!$B$2:$E$35,4,FALSE())-VLOOKUP(B19,Zones!$B$2:$E$35,4,FALSE()))^2),2),"") -> 8.29 | F19: =IFERROR(VLOOKUP(A19,Zones!$B$2:$E$35,4,FALSE()),"") -> 12.5 | G19: =IFERROR(VLOOKUP(B19,Zones!$B$2:$E$35,4,FALSE()),"") -> 15.21 | H19: =IFERROR(G19-F19,"") -> 2.71
A20: Xform_17 | B20: Xform_18 | C20: Y | D20: Y | E20: =IFERROR(ROUND(SQRT((VLOOKUP(A20,Zones!$B$2:$E$35,2,FALSE())-VLOOKUP(B20,Zones!$B$2:$E$35,2,FALSE()))^2+(VLOOKUP(A20,Zones!$B$2:$E$35,3,FALSE())-VLOOKUP(B20,Zones!$B$2:$E$35,3,FALSE()))^2+(VLOOKUP(A20,Zones!$B$2:$E$35,4,FALSE())-VLOOKUP(B20,Zones!$B$2:$E$35,4,FALSE()))^2),2),"") -> 7.12 | F20: =IFERROR(VLOOKUP(A20,Zones!$B$2:$E$35,4,FALSE()),"") -> 15.21 | G20: =IFERROR(VLOOKUP(B20,Zones!$B$2:$E$35,4,FALSE()),"") -> 17.19 | H20: =IFERROR(G20-F20,"") -> 1.98
A21: Xform_18 | B21: Xform_19 | C21: Y | D21: Y | E21: =IFERROR(ROUND(SQRT((VLOOKUP(A21,Zones!$B$2:$E$35,2,FALSE())-VLOOKUP(B21,Zones!$B$2:$E$35,2,FALSE()))^2+(VLOOKUP(A21,Zones!$B$2:$E$35,3,FALSE())-VLOOKUP(B21,Zones!$B$2:$E$35,3,FALSE()))^2+(VLOOKUP(A21,Zones!$B$2:$E$35,4,FALSE())-VLOOKUP(B21,Zones!$B$2:$E$35,4,FALSE()))^2),2),"") -> 7.74 | F21: =IFERROR(VLOOKUP(A21,Zones!$B$2:$E$35,4,FALSE()),"") -> 17.19 | G21: =IFERROR(VLOOKUP(B21,Zones!$B$2:$E$35,4,FALSE()),"") -> 18.83 | H21: =IFERROR(G21-F21,"") -> 1.64
A22: Xform_19 | B22: Xform_20 | C22: Y | D22: Y | E22: =IFERROR(ROUND(SQRT((VLOOKUP(A22,Zones!$B$2:$E$35,2,FALSE())-VLOOKUP(B22,Zones!$B$2:$E$35,2,FALSE()))^2+(VLOOKUP(A22,Zones!$B$2:$E$35,3,FALSE())-VLOOKUP(B22,Zones!$B$2:$E$35,3,FALSE()))^2+(VLOOKUP(A22,Zones!$B$2:$E$35,4,FALSE())-VLOOKUP(B22,Zones!$B$2:$E$35,4,FALSE()))^2),2),"") -> 10.95 | F22: =IFERROR(VLOOKUP(A22,Zones!$B$2:$E$35,4,FALSE()),"") -> 18.83 | G22: =IFERROR(VLOOKUP(B22,Zones!$B$2:$E$35,4,FALSE()),"") -> 20.59 | H22: =IFERROR(G22-F22,"") -> 1.76
A23: Xform_20 | B23: Xform_21 | C23: Y | D23: Y | E23: =IFERROR(ROUND(SQRT((VLOOKUP(A23,Zones!$B$2:$E$35,2,FALSE())-VLOOKUP(B23,Zones!$B$2:$E$35,2,FALSE()))^2+(VLOOKUP(A23,Zones!$B$2:$E$35,3,FALSE())-VLOOKUP(B23,Zones!$B$2:$E$35,3,FALSE()))^2+(VLOOKUP(A23,Zones!$B$2:$E$35,4,FALSE())-VLOOKUP(B23,Zones!$B$2:$E$35,4,FALSE()))^2),2),"") -> 12.16 | F23: =IFERROR(VLOOKUP(A23,Zones!$B$2:$E$35,4,FALSE()),"") -> 20.59 | G23: =IFERROR(VLOOKUP(B23,Zones!$B$2:$E$35,4,FALSE()),"") -> 22.37 | H23: =IFERROR(G23-F23,"") -> 1.78
A24: Xform_21 | B24: Xform_22 | C24: Y | D24: Y | E24: =IFERROR(ROUND(SQRT((VLOOKUP(A24,Zones!$B$2:$E$35,2,FALSE())-VLOOKUP(B24,Zones!$B$2:$E$35,2,FALSE()))^2+(VLOOKUP(A24,Zones!$B$2:$E$35,3,FALSE())-VLOOKUP(B24,Zones!$B$2:$E$35,3,FALSE()))^2+(VLOOKUP(A24,Zones!$B$2:$E$35,4,FALSE())-VLOOKUP(B24,Zones!$B$2:$E$35,4,FALSE()))^2),2),"") -> 11.63 | F24: =IFERROR(VLOOKUP(A24,Zones!$B$2:$E$35,4,FALSE()),"") -> 22.37 | G24: =IFERROR(VLOOKUP(B24,Zones!$B$2:$E$35,4,FALSE()),"") -> 24.64 | H24: =IFERROR(G24-F24,"") -> 2.27
A25: Xform_22 | B25: Xform_23 | C25: Y | D25: Y | E25: =IFERROR(ROUND(SQRT((VLOOKUP(A25,Zones!$B$2:$E$35,2,FALSE())-VLOOKUP(B25,Zones!$B$2:$E$35,2,FALSE()))^2+(VLOOKUP(A25,Zones!$B$2:$E$35,3,FALSE())-VLOOKUP(B25,Zones!$B$2:$E$35,3,FALSE()))^2+(VLOOKUP(A25,Zones!$B$2:$E$35,4,FALSE())-VLOOKUP(B25,Zones!$B$2:$E$35,4,FALSE()))^2),2),"") -> 4.34 | F25: =IFERROR(VLOOKUP(A25,Zones!$B$2:$E$35,4,FALSE()),"") -> 24.64 | G25: =IFERROR(VLOOKUP(B25,Zones!$B$2:$E$35,4,FALSE()),"") -> 25.69 | H25: =IFERROR(G25-F25,"") -> 1.05 | I25: Xform_23은 TP_D 의 최종 목적 좌표
A26: Xform_15 | B26: Xform_24 | C26: Y | D26: Y | E26: =IFERROR(ROUND(SQRT((VLOOKUP(A26,Zones!$B$2:$E$35,2,FALSE())-VLOOKUP(B26,Zones!$B$2:$E$35,2,FALSE()))^2+(VLOOKUP(A26,Zones!$B$2:$E$35,3,FALSE())-VLOOKUP(B26,Zones!$B$2:$E$35,3,FALSE()))^2+(VLOOKUP(A26,Zones!$B$2:$E$35,4,FALSE())-VLOOKUP(B26,Zones!$B$2:$E$35,4,FALSE()))^2),2),"") -> 5.74 | F26: =IFERROR(VLOOKUP(A26,Zones!$B$2:$E$35,4,FALSE()),"") -> 12.13 | G26: =IFERROR(VLOOKUP(B26,Zones!$B$2:$E$35,4,FALSE()),"") -> 14.25 | H26: =IFERROR(G26-F26,"") -> 2.12
A27: Xform_24 | B27: Xform_25 | C27: Y | D27: Y | E27: =IFERROR(ROUND(SQRT((VLOOKUP(A27,Zones!$B$2:$E$35,2,FALSE())-VLOOKUP(B27,Zones!$B$2:$E$35,2,FALSE()))^2+(VLOOKUP(A27,Zones!$B$2:$E$35,3,FALSE())-VLOOKUP(B27,Zones!$B$2:$E$35,3,FALSE()))^2+(VLOOKUP(A27,Zones!$B$2:$E$35,4,FALSE())-VLOOKUP(B27,Zones!$B$2:$E$35,4,FALSE()))^2),2),"") -> 6.18 | F27: =IFERROR(VLOOKUP(A27,Zones!$B$2:$E$35,4,FALSE()),"") -> 14.25 | G27: =IFERROR(VLOOKUP(B27,Zones!$B$2:$E$35,4,FALSE()),"") -> 16.29 | H27: =IFERROR(G27-F27,"") -> 2.04
A28: Xform_25 | B28: Xform_26 | C28: Y | D28: Y | E28: =IFERROR(ROUND(SQRT((VLOOKUP(A28,Zones!$B$2:$E$35,2,FALSE())-VLOOKUP(B28,Zones!$B$2:$E$35,2,FALSE()))^2+(VLOOKUP(A28,Zones!$B$2:$E$35,3,FALSE())-VLOOKUP(B28,Zones!$B$2:$E$35,3,FALSE()))^2+(VLOOKUP(A28,Zones!$B$2:$E$35,4,FALSE())-VLOOKUP(B28,Zones!$B$2:$E$35,4,FALSE()))^2),2),"") -> 4.8 | F28: =IFERROR(VLOOKUP(A28,Zones!$B$2:$E$35,4,FALSE()),"") -> 16.29 | G28: =IFERROR(VLOOKUP(B28,Zones!$B$2:$E$35,4,FALSE()),"") -> 17.67 | H28: =IFERROR(G28-F28,"") -> 1.38
A29: Xform_26 | B29: Xform_27 | C29: Y | D29: Y | E29: =IFERROR(ROUND(SQRT((VLOOKUP(A29,Zones!$B$2:$E$35,2,FALSE())-VLOOKUP(B29,Zones!$B$2:$E$35,2,FALSE()))^2+(VLOOKUP(A29,Zones!$B$2:$E$35,3,FALSE())-VLOOKUP(B29,Zones!$B$2:$E$35,3,FALSE()))^2+(VLOOKUP(A29,Zones!$B$2:$E$35,4,FALSE())-VLOOKUP(B29,Zones!$B$2:$E$35,4,FALSE()))^2),2),"") -> 5.33 | F29: =IFERROR(VLOOKUP(A29,Zones!$B$2:$E$35,4,FALSE()),"") -> 17.67 | G29: =IFERROR(VLOOKUP(B29,Zones!$B$2:$E$35,4,FALSE()),"") -> 18.84 | H29: =IFERROR(G29-F29,"") -> 1.17
A30: Xform_27 | B30: Xform_28 | C30: Y | D30: Y | E30: =IFERROR(ROUND(SQRT((VLOOKUP(A30,Zones!$B$2:$E$35,2,FALSE())-VLOOKUP(B30,Zones!$B$2:$E$35,2,FALSE()))^2+(VLOOKUP(A30,Zones!$B$2:$E$35,3,FALSE())-VLOOKUP(B30,Zones!$B$2:$E$35,3,FALSE()))^2+(VLOOKUP(A30,Zones!$B$2:$E$35,4,FALSE())-VLOOKUP(B30,Zones!$B$2:$E$35,4,FALSE()))^2),2),"") -> 7.12 | F30: =IFERROR(VLOOKUP(A30,Zones!$B$2:$E$35,4,FALSE()),"") -> 18.84 | G30: =IFERROR(VLOOKUP(B30,Zones!$B$2:$E$35,4,FALSE()),"") -> 19.17 | H30: =IFERROR(G30-F30,"") -> 0.33
A31: Xform_28 | B31: Xform_29 | C31: Y | D31: Y | E31: =IFERROR(ROUND(SQRT((VLOOKUP(A31,Zones!$B$2:$E$35,2,FALSE())-VLOOKUP(B31,Zones!$B$2:$E$35,2,FALSE()))^2+(VLOOKUP(A31,Zones!$B$2:$E$35,3,FALSE())-VLOOKUP(B31,Zones!$B$2:$E$35,3,FALSE()))^2+(VLOOKUP(A31,Zones!$B$2:$E$35,4,FALSE())-VLOOKUP(B31,Zones!$B$2:$E$35,4,FALSE()))^2),2),"") -> 7.22 | F31: =IFERROR(VLOOKUP(A31,Zones!$B$2:$E$35,4,FALSE()),"") -> 19.17 | G31: =IFERROR(VLOOKUP(B31,Zones!$B$2:$E$35,4,FALSE()),"") -> 19.45 | H31: =IFERROR(G31-F31,"") -> 0.28
A32: Xform_29 | B32: Xform_30 | C32: Y | D32: Y | E32: =IFERROR(ROUND(SQRT((VLOOKUP(A32,Zones!$B$2:$E$35,2,FALSE())-VLOOKUP(B32,Zones!$B$2:$E$35,2,FALSE()))^2+(VLOOKUP(A32,Zones!$B$2:$E$35,3,FALSE())-VLOOKUP(B32,Zones!$B$2:$E$35,3,FALSE()))^2+(VLOOKUP(A32,Zones!$B$2:$E$35,4,FALSE())-VLOOKUP(B32,Zones!$B$2:$E$35,4,FALSE()))^2),2),"") -> 3.51 | F32: =IFERROR(VLOOKUP(A32,Zones!$B$2:$E$35,4,FALSE()),"") -> 19.45 | G32: =IFERROR(VLOOKUP(B32,Zones!$B$2:$E$35,4,FALSE()),"") -> 19.89 | H32: =IFERROR(G32-F32,"") -> 0.44
A33: Xform_30 | B33: Xform_31 | C33: Y | D33: Y | E33: =IFERROR(ROUND(SQRT((VLOOKUP(A33,Zones!$B$2:$E$35,2,FALSE())-VLOOKUP(B33,Zones!$B$2:$E$35,2,FALSE()))^2+(VLOOKUP(A33,Zones!$B$2:$E$35,3,FALSE())-VLOOKUP(B33,Zones!$B$2:$E$35,3,FALSE()))^2+(VLOOKUP(A33,Zones!$B$2:$E$35,4,FALSE())-VLOOKUP(B33,Zones!$B$2:$E$35,4,FALSE()))^2),2),"") -> 3.85 | F33: =IFERROR(VLOOKUP(A33,Zones!$B$2:$E$35,4,FALSE()),"") -> 19.89 | G33: =IFERROR(VLOOKUP(B33,Zones!$B$2:$E$35,4,FALSE()),"") -> 20.44 | H33: =IFERROR(G33-F33,"") -> 0.55
A34: Xform_31 | B34: Xform_32 | C34: Y | D34: Y | E34: =IFERROR(ROUND(SQRT((VLOOKUP(A34,Zones!$B$2:$E$35,2,FALSE())-VLOOKUP(B34,Zones!$B$2:$E$35,2,FALSE()))^2+(VLOOKUP(A34,Zones!$B$2:$E$35,3,FALSE())-VLOOKUP(B34,Zones!$B$2:$E$35,3,FALSE()))^2+(VLOOKUP(A34,Zones!$B$2:$E$35,4,FALSE())-VLOOKUP(B34,Zones!$B$2:$E$35,4,FALSE()))^2),2),"") -> 3.64 | F34: =IFERROR(VLOOKUP(A34,Zones!$B$2:$E$35,4,FALSE()),"") -> 20.44 | G34: =IFERROR(VLOOKUP(B34,Zones!$B$2:$E$35,4,FALSE()),"") -> 21.06 | H34: =IFERROR(G34-F34,"") -> 0.62 | I34: Xform_32는 TP_C 의 최종 목적 좌표
C35: Y | D35: Y | E35: =IFERROR(ROUND(SQRT((VLOOKUP(A35,Zones!$B$2:$E$35,2,FALSE())-VLOOKUP(B35,Zones!$B$2:$E$35,2,FALSE()))^2+(VLOOKUP(A35,Zones!$B$2:$E$35,3,FALSE())-VLOOKUP(B35,Zones!$B$2:$E$35,3,FALSE()))^2+(VLOOKUP(A35,Zones!$B$2:$E$35,4,FALSE())-VLOOKUP(B35,Zones!$B$2:$E$35,4,FALSE()))^2),2),"") | F35: =IFERROR(VLOOKUP(A35,Zones!$B$2:$E$35,4,FALSE()),"") | G35: =IFERROR(VLOOKUP(B35,Zones!$B$2:$E$35,4,FALSE()),"") | H35: =IFERROR(G35-F35,"")
C36: Y | D36: Y | E36: =IFERROR(ROUND(SQRT((VLOOKUP(A36,Zones!$B$2:$E$35,2,FALSE())-VLOOKUP(B36,Zones!$B$2:$E$35,2,FALSE()))^2+(VLOOKUP(A36,Zones!$B$2:$E$35,3,FALSE())-VLOOKUP(B36,Zones!$B$2:$E$35,3,FALSE()))^2+(VLOOKUP(A36,Zones!$B$2:$E$35,4,FALSE())-VLOOKUP(B36,Zones!$B$2:$E$35,4,FALSE()))^2),2),"") | F36: =IFERROR(VLOOKUP(A36,Zones!$B$2:$E$35,4,FALSE()),"") | G36: =IFERROR(VLOOKUP(B36,Zones!$B$2:$E$35,4,FALSE()),"") | H36: =IFERROR(G36-F36,"")
C37: Y | D37: Y | E37: =IFERROR(ROUND(SQRT((VLOOKUP(A37,Zones!$B$2:$E$35,2,FALSE())-VLOOKUP(B37,Zones!$B$2:$E$35,2,FALSE()))^2+(VLOOKUP(A37,Zones!$B$2:$E$35,3,FALSE())-VLOOKUP(B37,Zones!$B$2:$E$35,3,FALSE()))^2+(VLOOKUP(A37,Zones!$B$2:$E$35,4,FALSE())-VLOOKUP(B37,Zones!$B$2:$E$35,4,FALSE()))^2),2),"") | F37: =IFERROR(VLOOKUP(A37,Zones!$B$2:$E$35,4,FALSE()),"") | G37: =IFERROR(VLOOKUP(B37,Zones!$B$2:$E$35,4,FALSE()),"") | H37: =IFERROR(G37-F37,"")
C38: Y | D38: Y | E38: =IFERROR(ROUND(SQRT((VLOOKUP(A38,Zones!$B$2:$E$35,2,FALSE())-VLOOKUP(B38,Zones!$B$2:$E$35,2,FALSE()))^2+(VLOOKUP(A38,Zones!$B$2:$E$35,3,FALSE())-VLOOKUP(B38,Zones!$B$2:$E$35,3,FALSE()))^2+(VLOOKUP(A38,Zones!$B$2:$E$35,4,FALSE())-VLOOKUP(B38,Zones!$B$2:$E$35,4,FALSE()))^2),2),"") | F38: =IFERROR(VLOOKUP(A38,Zones!$B$2:$E$35,4,FALSE()),"") | G38: =IFERROR(VLOOKUP(B38,Zones!$B$2:$E$35,4,FALSE()),"") | H38: =IFERROR(G38-F38,"")
C39: Y | D39: Y | E39: =IFERROR(ROUND(SQRT((VLOOKUP(A39,Zones!$B$2:$E$35,2,FALSE())-VLOOKUP(B39,Zones!$B$2:$E$35,2,FALSE()))^2+(VLOOKUP(A39,Zones!$B$2:$E$35,3,FALSE())-VLOOKUP(B39,Zones!$B$2:$E$35,3,FALSE()))^2+(VLOOKUP(A39,Zones!$B$2:$E$35,4,FALSE())-VLOOKUP(B39,Zones!$B$2:$E$35,4,FALSE()))^2),2),"") | F39: =IFERROR(VLOOKUP(A39,Zones!$B$2:$E$35,4,FALSE()),"") | G39: =IFERROR(VLOOKUP(B39,Zones!$B$2:$E$35,4,FALSE()),"") | H39: =IFERROR(G39-F39,"")
C40: Y | D40: Y | E40: =IFERROR(ROUND(SQRT((VLOOKUP(A40,Zones!$B$2:$E$35,2,FALSE())-VLOOKUP(B40,Zones!$B$2:$E$35,2,FALSE()))^2+(VLOOKUP(A40,Zones!$B$2:$E$35,3,FALSE())-VLOOKUP(B40,Zones!$B$2:$E$35,3,FALSE()))^2+(VLOOKUP(A40,Zones!$B$2:$E$35,4,FALSE())-VLOOKUP(B40,Zones!$B$2:$E$35,4,FALSE()))^2),2),"") | F40: =IFERROR(VLOOKUP(A40,Zones!$B$2:$E$35,4,FALSE()),"") | G40: =IFERROR(VLOOKUP(B40,Zones!$B$2:$E$35,4,FALSE()),"") | H40: =IFERROR(G40-F40,"")
...

Sheet README
A1: Routing_Zones 링크 설정표 (zone 인접 그래프 정의용)
A3: ★ '링크' 의 의미 (중요)
A4: - 링크는 두 zone 사이의 **인접 허용 선언** — '이 zone 에서 저 zone 으로 직접 갈 수 있다' 는 그래프 edge
A5: - 직선 경로를 강제하는 게 아님. 실제 이동 경로는 Nav2 가 obstacle/지형 회피하며 자동 plan
A6: - 링크 없는 zone 쌍은 인접하지 않음 → Dijkstra 가 다른 zone 들을 경유하는 경로를 찾음
A7: - 예: A↔B, B↔C 만 연결 → A 에서 C 로 가려면 반드시 B 경유
A9: 사용법
A10: 1. Links 시트 From / To 셀에서 dropdown 으로 zone 이름 선택 → 인접쌍 한 행
A11: 2. Bidirectional: Y = 양방향 (A↔B), N = 단방향 (From → To 만)
A12: 3. Enabled: Y = 활성, N = 비활성 (그래프 빌드 시 무시)
A13: 4. StraightDist_m / From_Z / To_Z / ΔZ 는 자동 계산 (참고용, 편집 금지)
A14: - 두 zone 간 직선거리 — Dijkstra cost hint 로만 사용. 실제 경로 길이 아님
... A25: 총 zone: 34개 | 생성일: 2026-05-26
